String value is: <?xml version="1.0" ?> <!-- =================================================================================== --> <!-- |    This document was autogenerated by xacro from /ros2_ws/install/my_robot_description/share/my_robot_description/urdf/my_robot.urdf.xacro | --> <!-- |    EDITING THIS FILE BY HAND IS NOT RECOMMENDED                                 | --> <!-- =================================================================================== --> <!-- Dummy commit --> <robot name="my_robot"> <!-- Added xacro function for modularity --> <material name="red"> <color rgba="1 0 0 1"/> </material> <material name="blue"> <color rgba="0 0 1 1"/> </material> <material name="grey"> <color rgba="0.5 0.5 0.5 1"/> </material> <material name="black"> <color rgba="0 0 0 1"/> </material> <link name="base_link"> <visual> <geometry> <box size="0.6 0.4 0.2"/> </geometry> <origin rpy="0 0 0" xyz="0 0 0.1"/> <material name="blue"/> </visual> <inertial> <mass value="5.0"/> <origin rpy="0 0 0" xyz="0 0 0.1"/> <inertia ixx="0.08333333333333334" ixy="0.0" ixz="0.0" iyy="0.16666666666666666" iyz="0.0" izz="0.21666666666666665"/> </inertial> <collision> <geometry> <box size="0.6 0.4 0.2"/> </geometry> <origin rpy="0 0 0" xyz="0 0 0.1"/> </collision> </link> <link name="base_footprint"> </link> <link name="right_wheel_link"> <visual> <geometry> <cylinder length="0.05" radius="0.1"/> </geometry> <origin rpy="1.5708 0 0" xyz="0 0 0"/> <material name="grey"/> </visual> <inertial> <mass value="1.0"/> <origin rpy="1.5708 0 0" xyz="0 0 0"/> <inertia ixx="0.002708333333333334" ixy="0.0" ixz="0.0" iyy="0.002708333333333334" iyz="0.0" izz="0.005000000000000001"/> </inertial> <collision> <geometry> <cylinder length="0.05" radius="0.1"/> </geometry> <origin rpy="1.5708 0 0" xyz="0 0 0"/> </collision> </link> <link name="left_wheel_link"> <visual> <geometry> <cylinder length="0.05" radius="0.1"/> </geometry> <origin rpy="1.5708 0 0" xyz="0 0 0"/> <material name="grey"/> </visual> <inertial> <mass value="1.0"/> <origin rpy="1.5708 0 0" xyz="0 0 0"/> <inertia ixx="0.002708333333333334" ixy="0.0" ixz="0.0" iyy="0.002708333333333334" iyz="0.0" izz="0.005000000000000001"/> </inertial> <collision> <geometry> <cylinder length="0.05" radius="0.1"/> </geometry> <origin rpy="1.5708 0 0" xyz="0 0 0"/> </collision> </link> <link name="castor_wheel_link"> <visual> <geometry> <sphere radius="0.05"/> </geometry> <origin rpy="0 0 0" xyz="0 0 -0.05"/> <material name="grey"/> </visual> <inertial> <mass value="0.5"/> <origin rpy="0 0 0" xyz="0 0 -0.05"/> <inertia ixx="0.0005000000000000001" ixy="0.0" ixz="0.0" iyy="0.0005000000000000001" iyz="0.0" izz="0.0005000000000000001"/> </inertial> <collision> <geometry> <sphere radius="0.05"/> </geometry> <origin rpy="0 0 0" xyz="0 0 -0.05"/> </collision> </link> <joint name="base_to_right_wheel" type="continuous"> <parent link="base_link"/> <child link="right_wheel_link"/> <origin rpy="0 0 0" xyz="-0.15 -0.225 0"/> <axis xyz="0 1 0"/> <limit effort="10.0" velocity="10.0"/> <dynamics damping="1.0" friction="1.0"/> </joint> <joint name="base_to_left_wheel" type="continuous"> <parent link="base_link"/> <child link="left_wheel_link"/> <origin rpy="0 0 0" xyz="-0.15 0.225 0"/> <axis xyz="0 1 0"/> <limit effort="10.0" velocity="10.0"/> <dynamics damping="1.0" friction="1.0"/> </joint> <joint name="base_to_castor_wheel" type="fixed"> <parent link="base_link"/> <child link="castor_wheel_link"/> <origin rpy="0 0 0" xyz="0.19999999999999998 0 0"/> </joint> <joint name="base_joint" type="fixed"> <parent link="base_footprint"/> <child link="base_link"/> <origin rpy="0 0 0" xyz="0 0 .1"/> <axis xyz="0 0 1"/> </joint> <!-- ================= ROS2 CONTROL ================= --> <ros2_control name="MobileBaseHardware" type="system"> <hardware> <plugin>gz_ros2_control/GazeboSimSystem</plugin> <!-- <param name="serial_port">/dev/ttyUSB0</param> <param name="baud_rate">115200</param> <param name="counts_per_rev">1260.0</param> <param name="wheel_radius">0.035</param> <param name="wheel_base">0.34</param> --> </hardware> <joint name="base_to_left_wheel"> <command_interface name="velocity"/> <state_interface name="position"/> <state_interface name="velocity"/> <state_interface name="effort"/> </joint> <joint name="base_to_right_wheel"> <command_interface name="velocity"/> <state_interface name="position"/> <state_interface name="velocity"/> <state_interface name="effort"/> </joint> </ros2_control> <!-- ================= GAZEBO PLUGIN ================= --> <!-- <gazebo> <plugin filename="gz_ros2_control-system" name="gz_ros2_control::GazeboSimROS2ControlPlugin"> <parameters>$(find my_robot_bringup)/config/my_robot_controllers.yaml</parameters> </plugin> </gazebo> --> <!-- ================= GAZEBO PLUGIN ================= --> <gazebo> <plugin filename="/opt/ros/jazzy/lib/libgz_ros2_control-system.so" name="gz_ros2_control::GazeboSimROS2ControlPlugin"> <parameters>/ros2_ws/install/my_robot_bringup/share/my_robot_bringup/config/my_robot_controllers.yaml</parameters> </plugin> </gazebo> <link name="camera_link"> <visual> <geometry> <box size="0.01 0.1 0.05"/> </geometry> <material name="grey"/> </visual> <collision> <geometry> <box size="0.01 0.1 0.05"/> </geometry> </collision> <inertial> <mass value="0.1"/> <origin rpy="0 0 0" xyz="0 0 0"/> <inertia ixx="0.00010416666666666669" ixy="0.0" ixz="0.0" iyy="2.166666666666667e-05" iyz="0.0" izz="8.416666666666668e-05"/> </inertial> </link> <joint name="base_camera_joint" type="fixed"> <parent link="base_link"/> <child link="camera_link"/> <origin rpy="0 0 0" xyz="0.305 0 0.1"/> </joint> <link name="camera_link_optical"/> <joint name="camera_optical_joint" type="fixed"> <origin rpy="-1.5707963267948966 0 -1.5707963267948966" xyz="0 0 0"/> <parent link="camera_link"/> <child link="camera_link_optical"/> </joint> <gazebo reference="camera_link"> <sensor name="camera" type="camera"> <camera> <horizontal_fov>1.3962634</horizontal_fov> <image> <width>640</width> <height>480</height> <format>R8G8B8</format> </image> <clip> <near>0.1</near> <far>15</far> </clip> <noise> <type>gaussian</type> <mean>0.0</mean> <stddev>0.007</stddev> </noise> <optical_frame_id>camera_link_optical</optical_frame_id> <camera_info_topic>/camera_info</camera_info_topic> </camera> <always_on>1</always_on> <update_rate>20</update_rate> <visualize>true</visualize> <topic>/camera</topic> </sensor> </gazebo> <!-- Lidar link --> <link name="lidar_link"> <visual> <geometry> <cylinder length="0.1" radius="0.05"/> </geometry> <origin rpy="0 0 0" xyz="0 0 0"/> <material name="black"/> </visual> <collision> <geometry> <cylinder length="0.1" radius="0.05"/> </geometry> <origin rpy="0 0 0" xyz="0 0 0"/> </collision> <inertial> <mass value="0.5"/> <origin rpy="0 0 0" xyz="0 0 0"/> <inertia ixx="0.0007291666666666667" ixy="0.0" ixz="0.0" iyy="0.0007291666666666667" iyz="0.0" izz="0.0006250000000000001"/> </inertial> </link> <!-- Lidar joint (attach to base_link) --> <joint name="lidar_joint" type="fixed"> <parent link="base_link"/> <child link="lidar_link"/> <origin rpy="0 0 0" xyz="0 0 0.25"/> </joint> <!-- Gazebo Lidar sensor plugin --> <gazebo reference="lidar_link"> <sensor name="lidar" type="gpu_lidar"> <gz_frame_id>lidar_link</gz_frame_id> <update_rate>20</update_rate> <visualize>true</visualize> <visualize_type>rays</visualize_type> <ray> <scan> <horizontal> <samples>360</samples> <resolution>1</resolution> <min_angle>-3.14159</min_angle> <max_angle>3.14159</max_angle> </horizontal> </scan> <range> <min>0.12</min> <max>3.5</max> <resolution>0.01</resolution> </range> <noise> <type>gaussian</type> <mean>0.0</mean> <stddev>0.01</stddev> </noise> </ray> </sensor> </gazebo> <link name="imu_link"> <visual> <geometry> <box size="0.02 0.02 0.02"/> </geometry> </visual> <collision> <geometry> <box size="0.02 0.02 0.02"/> </geometry> </collision> <inertial> <mass value="0.01"/> <origin xyz="0 0 0"/> <inertia ixx="0.00001" ixy="0" ixz="0" iyy="0.00001" iyz="0" izz="0.00001"/> </inertial> </link> <joint name="imu_joint" type="fixed"> <parent link="base_link"/> <child link="imu_link"/> <origin rpy="0 0 0" xyz="0.305 0 0.2"/> </joint> <gazebo reference="imu_link"> <sensor name="imu_sensor" type="imu"> <always_on>true</always_on> <update_rate>100</update_rate> <visualize>true</visualize> <topic>imu</topic> </sensor> </gazebo> <!-- <xacro:include filename="mobile_base_gazebo.xacro"/> --> </robot>
